<mujoco model="m0617">

  <asset>
    <mesh name="MF0617_0_0" file="m0617/assets/MF0617_0_0.stl" scale="0.001 0.001 0.001"/>
    <mesh name="MF0617_1_0" file="m0617/assets/MF0617_1_0.stl" scale="0.001 0.001 0.001"/>
    <mesh name="MF0617_2_0" file="m0617/assets/MF0617_2_0.stl" scale="0.001 0.001 0.001"/>
    <mesh name="MF0617_2_1" file="m0617/assets/MF0617_2_1.stl" scale="0.001 0.001 0.001"/>
    <mesh name="MF0617_2_2" file="m0617/assets/MF0617_2_2.stl" scale="0.001 0.001 0.001"/>
    <mesh name="MF0617_3_0" file="m0617/assets/MF0617_3_0.stl" scale="0.001 0.001 0.001"/>
    <mesh name="MF0617_4_0" file="m0617/assets/MF0617_4_0.stl" scale="0.001 0.001 0.001"/>
    <mesh name="MF0617_4_1" file="m0617/assets/MF0617_4_1.stl" scale="0.001 0.001 0.001"/>
    <mesh name="MF0617_5_0" file="m0617/assets/MF0617_5_0.stl" scale="0.001 0.001 0.001"/>
    <mesh name="MF0617_6_0" file="m0617/assets/MF0617_6_0.stl" scale="0.001 0.001 0.001"/>

    <material name="white" rgba="0.9 0.9 0.9 1"/>
    <material name="metal" rgba="0.65 0.65 0.65 1"/>
  </asset>

  <worldbody>
    <geom type="mesh" contype="1" conaffinity="1" density="0" group="1" mesh="MF0617_0_0" material="metal"/>
    <body name="link_1" pos="0 0 0.1530">
      <inertial pos="0.000119 0.0428 -0.006383" quat="0.254665 0.28969 -0.691124 0.611207" mass="7.8" diaginertia="0.0473264 0.0472093 0.0309423"/>
      <joint name="joint_1" pos="0 0 0" axis="0 0 1" range="-6.2832 6.2832" actuatorfrcrange="-346 346" damping="1600" frictionloss="1"/>
      <geom type="mesh" contype="1" conaffinity="1" density="0" group="1" mesh="MF0617_1_0" material="white"/>
      <body name="link_2" pos="0 0.0345 0" quat="0.499898 -0.500102 -0.5 -0.5">
        <inertial pos="0.35752 -5e-05 0.1582" quat="0.0100079 0.704803 0.0101714 0.709259" mass="11.55" diaginertia="1.62606 1.6244 0.0391819"/>
        <joint name="joint_2" pos="0 0 0" axis="0 0 1" range="-6.2832 6.2832" actuatorfrcrange="-346 346" damping="1600" frictionloss="1"/>
        <geom type="mesh" contype="1" conaffinity="1" density="0" group="1" mesh="MF0617_2_0" material="white"/>
        <geom type="mesh" contype="1" conaffinity="1" density="0" group="1" mesh="MF0617_2_1" material="metal"/>
        <geom type="mesh" contype="1" conaffinity="1" density="0" group="1" mesh="MF0617_2_2" material="white"/>
        <body name="link_3" pos="0.845 0 0" quat="0.707035 0 0 0.707179">
          <inertial pos="-1.5e-05 -0.006702 0.044608" quat="0.995174 -0.0980322 0.000308705 0.00417616" mass="3.68" diaginertia="0.0205791 0.0193788 0.0141811"/>
          <joint name="joint_3" pos="0 0 0" axis="0 0 1" range="-2.8798 2.8798" actuatorfrcrange="-163 163" damping="1300" frictionloss="1"/>
          <geom type="mesh" contype="1" conaffinity="1" density="0" group="1" mesh="MF0617_3_0" material="white"/>
          <body name="link_4" pos="0 -0.734 0" quat="0.707035 0.707179 0 0">
            <inertial pos="5.7e-05 0.091288 -0.25319" quat="0.99323 -0.116156 -0.000123673 -0.0017187" mass="4.28" diaginertia="0.35652 0.354528 0.0115856"/>
            <joint name="joint_4" pos="0 0 0" axis="0 0 1" range="-6.2832 6.2832" actuatorfrcrange="-50 50" damping="1050" frictionloss="1"/>
            <geom type="mesh" contype="1" conaffinity="1" density="0" group="1" mesh="MF0617_4_0" material="white"/>
            <geom type="mesh" contype="1" conaffinity="1" density="0" group="1" mesh="MF0617_4_1" material="white"/>
            <body name="link_5" quat="0.707035 -0.707179 0 0">
              <inertial pos="-0.000273 0.003651 0.032087" quat="0.710739 0.05419 -0.0499513 0.699584" mass="2.8" diaginertia="0.0132957 0.0120157 0.0103596"/>
              <joint name="joint_5" pos="0 0 0" axis="0 0 1" range="-6.2832 6.2832" actuatorfrcrange="-50 50" damping="1050" frictionloss="1"/>
              <geom type="mesh" contype="1" conaffinity="1" density="0" group="1" mesh="MF0617_5_0" material="white"/>
              <body name="link_6" pos="0 -0.121 0" quat="0.707035 0.707179 0 0">
                <inertial pos="-0.000292 7e-06 -0.0539" quat="0.53756 0.537199 -0.459029 0.460152" mass="1.16" diaginertia="0.00867762 0.00864399 0.00456129"/>
                <joint name="joint_6" pos="0 0 0" axis="0 0 1" range="-6.2832 6.2832" actuatorfrcrange="-50 50" damping="1050" frictionloss="1"/>
                <geom type="mesh" contype="1" conaffinity="1" density="0" group="1" mesh="MF0617_6_0" material="metal"/>
              </body>
            </body>
          </body>
        </body>
      </body>
    </body>
  </worldbody>

	<actuator>
		<position joint="joint_1" kp="10" kv="1" ctrlrange="-6.2832 6.2832"/>
		<position joint="joint_2" kp="10" kv="1" ctrlrange="-6.2832 6.2832"/>
		<position joint="joint_3" kp="10" kv="1" ctrlrange="-2.8798 2.8798"/>
		<position joint="joint_4" kp="10" kv="1" ctrlrange="-6.2832 6.2832"/>
		<position joint="joint_5" kp="10" kv="1" ctrlrange="-6.2832 6.2832"/>
		<position joint="joint_6" kp="10" kv="1" ctrlrange="-6.2832 6.2832"/>
	</actuator>
</mujoco>
