<mujoco model="h2515">

  <asset>
    <mesh name="H2515_0_0" file="h2515/assets/H2515_0_0.stl" scale="0.001 0.001 0.001"/>
    <mesh name="H2515_1_0" file="h2515/assets/H2515_1_0.stl" scale="0.001 0.001 0.001"/>
    <mesh name="H2515_2_0" file="h2515/assets/H2515_2_0.stl" scale="0.001 0.001 0.001"/>
    <mesh name="H2515_2_1" file="h2515/assets/H2515_2_1.stl" scale="0.001 0.001 0.001"/>
    <mesh name="H2515_2_2" file="h2515/assets/H2515_2_2.stl" scale="0.001 0.001 0.001"/>
    <mesh name="H2515_3_0" file="h2515/assets/H2515_3_0.stl" scale="0.001 0.001 0.001"/>
    <mesh name="H2515_4_0" file="h2515/assets/H2515_4_0.stl" scale="0.001 0.001 0.001"/>
    <mesh name="H2515_4_1" file="h2515/assets/H2515_4_1.stl" scale="0.001 0.001 0.001"/>
    <mesh name="H2515_5_0" file="h2515/assets/H2515_5_0.stl" scale="0.001 0.001 0.001"/>
    <mesh name="H2515_6_0" file="h2515/assets/H2515_6_0.stl" scale="0.001 0.001 0.001"/>

    <material name="blue" rgba="0.227 0.251 0.31 1"/>
    <material name="metal" rgba="0.65 0.65 0.65 1"/>
  </asset>

  <worldbody>
    <geom type="mesh" contype="1" conaffinity="1" group="1" density="0" mesh="H2515_0_0" material="metal"/>
    <body name="link_1" pos="0 0 0.3443">
      <inertial pos="-5.3e-05 0.11854 -0.059979" quat="0.433455 0.901175 -0.000249559 4.48567e-05" mass="20.253" diaginertia="0.52872 0.466466 0.160934"/>
      <joint name="joint_1" pos="0 0 0" axis="0 0 1" range="-6.2832 6.2832" actuatorfrcrange="-372 372" damping="1500"/>
      <geom type="mesh" contype="1" conaffinity="1" group="1" density="0" mesh="H2515_1_0" material="blue"/>
      <body name="link_2" pos="0 0.0099 0" quat="0.499898 -0.500102 -0.5 -0.5">
        <inertial pos="0.35729 -2.4e-05 0.22527" quat="0.488728 0.510966 0.511785 0.48799" mass="28.111" diaginertia="2.5113 2.47463 0.147111"/>
        <joint name="joint_2" pos="0 0 0" axis="0 0 1" range="-2.1817 2.1817" actuatorfrcrange="-372 372" damping="1500"/>
        <geom type="mesh" contype="1" conaffinity="1" group="1" density="0" mesh="H2515_2_0" material="blue"/>
        <geom type="mesh" contype="1" conaffinity="1" group="1" density="0" mesh="H2515_2_1" material="metal"/>
        <geom type="mesh" contype="1" conaffinity="1" group="1" density="0" mesh="H2515_2_2" material="blue"/>
        <body name="link_3" pos="0.7595 0 0" quat="0.707035 0 0 0.707179">
          <inertial pos="-6.5e-05 -0.0074124 0.049527" quat="0.992581 -0.121367 0.00102818 0.00719059" mass="6.421" diaginertia="0.0423385 0.0401607 0.0273598"/>
          <joint name="joint_3" pos="0 0 0" axis="0 0 1" range="-2.7925 2.7925" actuatorfrcrange="-372 372" damping="1500"/>
          <geom type="mesh" contype="1" conaffinity="1" group="1" density="0" mesh="H2515_3_0" material="blue"/>
          <body name="link_4" pos="0 -0.6195 0" quat="0.707035 0.707179 0 0">
            <inertial pos="7.9e-05 0.13068 -0.17947" quat="0.984108 -0.177548 -0.000316986 -0.00266865" mass="7.295" diaginertia="0.41598 0.410877 0.0291385"/>
            <joint name="joint_4" pos="0 0 0" axis="0 0 1" range="-6.2832 6.2832" actuatorfrcrange="-163 163" damping="1200"/>
            <geom type="mesh" contype="1" conaffinity="1" group="1" density="0" mesh="H2515_4_0" material="blue"/>
            <geom type="mesh" contype="1" conaffinity="1" group="1" density="0" mesh="H2515_4_1" material="blue"/>
            <body name="link_5" quat="0.707035 -0.707179 0 0">
              <inertial pos="-6.1e-05 -0.000589 0.048788" quat="0.99979 0.00242364 0.000186085 0.0203461" mass="4.099" diaginertia="0.0247849 0.0242284 0.0122177"/>
              <joint name="joint_5" pos="0 0 0" axis="0 0 1" range="-6.2832 6.2832" actuatorfrcrange="-96 96" damping="1000"/>
              <geom type="mesh" contype="1" conaffinity="1" group="1" density="0" mesh="H2515_5_0" material="blue"/>
              <body name="link_6" pos="0 -0.121 0" quat="0.707035 0.707179 0 0">
                <inertial pos="-3.3e-05 1.2e-05 -0.049444" quat="0.708541 0.705011 -0.0182402 0.0244064" mass="0.897" diaginertia="0.00812142 0.00799787 0.00719801"/>
                <joint name="joint_6" pos="0 0 0" axis="0 0 1" range="-6.2832 6.2832" actuatorfrcrange="-50 50" damping="1000"/>
                <geom type="mesh" contype="1" conaffinity="1" group="1" density="0" mesh="H2515_6_0" material="metal"/>
              </body>
            </body>
          </body>
        </body>
      </body>
    </body>
  </worldbody>

	<actuator>
		<position joint="joint_1" kp="10" kv="1" ctrlrange="-6.2832 6.2832"/>
		<position joint="joint_2" kp="10" kv="1" ctrlrange="-2.1817 2.1817"/>
		<position joint="joint_3" kp="10" kv="1" ctrlrange="-2.7925 2.7925"/>
		<position joint="joint_4" kp="10" kv="1" ctrlrange="-6.2832 6.2832"/>
		<position joint="joint_5" kp="10" kv="1" ctrlrange="-6.2832 6.2832"/>
		<position joint="joint_6" kp="10" kv="1" ctrlrange="-6.2832 6.2832"/>
	</actuator>
  
</mujoco>
