<mujoco model="m1509">

  <asset>
    <mesh name="MF1509_0_0" file="m1509/assets/MF1509_0_0.stl" scale="0.001 0.001 0.001"/>
    <mesh name="MF1509_1_0" file="m1509/assets/MF1509_1_0.stl" scale="0.001 0.001 0.001"/>
    <mesh name="MF1509_2_0" file="m1509/assets/MF1509_2_0.stl" scale="0.001 0.001 0.001"/>
    <mesh name="MF1509_2_1" file="m1509/assets/MF1509_2_1.stl" scale="0.001 0.001 0.001"/>
    <mesh name="MF1509_2_2" file="m1509/assets/MF1509_2_2.stl" scale="0.001 0.001 0.001"/>
    <mesh name="MF1509_3_0" file="m1509/assets/MF1509_3_0.stl" scale="0.001 0.001 0.001"/>
    <mesh name="MF1509_4_0" file="m1509/assets/MF1509_4_0.stl" scale="0.001 0.001 0.001"/>
    <mesh name="MF1509_4_1" file="m1509/assets/MF1509_4_1.stl" scale="0.001 0.001 0.001"/>
    <mesh name="MF1509_5_0" file="m1509/assets/MF1509_5_0.stl" scale="0.001 0.001 0.001"/>
    <mesh name="MF1509_6_0" file="m1509/assets/MF1509_6_0.stl" scale="0.001 0.001 0.001"/>

    <material name="white" rgba="0.9 0.9 0.9 1"/>
    <material name="metal" rgba="0.65 0.65 0.65 1"/>
  </asset>

  <worldbody>
    <geom type="mesh" contype="1" conaffinity="1" density="0" group="1" mesh="MF1509_0_0" material="metal"/>
    <body name="link_1" pos="0 0 0.1525">
      <inertial pos="0.000119 0.0428 -0.006382" quat="0.407308 0.459354 -0.589466 0.524999" mass="7.8" diaginertia="0.0477106 0.0474663 0.0305311"/>
      <joint name="joint_1" pos="0 0 0" axis="0 0 1" range="-6.2832 6.2832" actuatorfrcrange="-346 346" damping="2000" frictionloss="1"/>
      <geom type="mesh" contype="1" conaffinity="1" density="0" group="1" mesh="MF1509_1_0" material="white"/>
      <body name="link_2" pos="0 0.0345 0" quat="0.499898 -0.500102 -0.5 -0.5">
        <inertial pos="0.17059 -5.8e-05 0.15734" quat="0.495058 0.504288 0.488025 0.512291" mass="10.06" diaginertia="0.370102 0.368734 0.0369837"/>
        <joint name="joint_2" pos="0 0 0" axis="0 0 1" range="-6.2832 6.2832" actuatorfrcrange="-346 346" damping="2000" frictionloss="1"/>
        <geom type="mesh" contype="1" conaffinity="1" density="0" group="1" mesh="MF1509_2_0" material="white"/>
        <geom type="mesh" contype="1" conaffinity="1" density="0" group="1" mesh="MF1509_2_1" material="metal"/>
        <geom type="mesh" contype="1" conaffinity="1" density="0" group="1" mesh="MF1509_2_2" material="white"/>
        <body name="link_3" pos="0.411 0 0" quat="0.707035 0 0 0.707179">
          <inertial pos="-1.5e-05 -0.00671 0.044632" quat="0.993891 -0.110354 0.000285252 0.00135996" mass="3.68" diaginertia="0.019496 0.015527 0.010871"/>
          <joint name="joint_3" pos="0 0 0" axis="0 0 1" range="-2.618 2.618" actuatorfrcrange="-163 163" damping="1400" frictionloss="1"/>
          <geom type="mesh" contype="1" conaffinity="1" density="0" group="1" mesh="MF1509_3_0" material="white"/>
          <body name="link_4" pos="0 -0.368 0" quat="0.707035 0.707179 0 0">
            <inertial pos="3.9e-05 0.09731 -0.1096" quat="0.969704 -0.244282 1.79483e-05 -0.00020735" mass="3.59" diaginertia="0.082012 0.0791784 0.00968264"/>
            <joint name="joint_4" pos="0 0 0" axis="0 0 1" range="-6.2832 6.2832" actuatorfrcrange="-50 50" damping="1000" frictionloss="1"/>
            <geom type="mesh" contype="1" conaffinity="1" density="0" group="1" mesh="MF1509_4_0" material="white"/>
            <geom type="mesh" contype="1" conaffinity="1" density="0" group="1" mesh="MF1509_4_1" material="white"/>
            <body name="link_5" quat="0.707035 -0.707179 0 0">
              <inertial pos="-6.9e-05 0.003827 0.032006" quat="0.998488 0.0548816 -0.000234048 0.00324916" mass="2.83" diaginertia="0.0168711 0.0138161 0.00971929"/>
              <joint name="joint_5" pos="0 0 0" axis="0 0 1" range="-6.2832 6.2832" actuatorfrcrange="-50 50" damping="1000" frictionloss="1"/>
              <geom type="mesh" contype="1" conaffinity="1" density="0" group="1" mesh="MF1509_5_0" material="white"/>
              <body name="link_6" pos="0 -0.121 0" quat="0.707035 0.707179 0 0">
                <inertial pos="-3.2e-05 8e-06 -0.0539" quat="0.493691 0.507293 -0.491957 0.506855" mass="1.16" diaginertia="0.00713731 0.00485237 0.00475452"/>
                <joint name="joint_6" pos="0 0 0" axis="0 0 1" range="-6.2832 6.2832" actuatorfrcrange="-50 50" damping="1000" frictionloss="1"/>
                <geom type="mesh" contype="1" conaffinity="1" density="0" group="1" mesh="MF1509_6_0" material="metal"/>
              </body>
            </body>
          </body>
        </body>
      </body>
    </body>
  </worldbody>

	<actuator>
		<position joint="joint_1" kp="10" kv="1" ctrlrange="-6.2832 6.2832"/>
		<position joint="joint_2" kp="10" kv="1" ctrlrange="-6.2832 6.2832"/>
		<position joint="joint_3" kp="10" kv="1" ctrlrange="-2.618 2.618"/>
		<position joint="joint_4" kp="10" kv="1" ctrlrange="-6.2832 6.2832"/>
		<position joint="joint_5" kp="10" kv="1" ctrlrange="-6.2832 6.2832"/>
		<position joint="joint_6" kp="10" kv="1" ctrlrange="-6.2832 6.2832"/>
	</actuator>
</mujoco>
