<mujoco model="h2017">

  <asset>
    <mesh name="H2017_0_0" file="h2017/assets/H2017_0_0.stl" scale="0.001 0.001 0.001"/>
    <mesh name="H2017_1_0" file="h2017/assets/H2017_1_0.stl" scale="0.001 0.001 0.001"/>
    <mesh name="H2017_2_0" file="h2017/assets/H2017_2_0.stl" scale="0.001 0.001 0.001"/>
    <mesh name="H2017_2_1" file="h2017/assets/H2017_2_1.stl" scale="0.001 0.001 0.001"/>
    <mesh name="H2017_2_2" file="h2017/assets/H2017_2_2.stl" scale="0.001 0.001 0.001"/>
    <mesh name="H2017_3_0" file="h2017/assets/H2017_3_0.stl" scale="0.001 0.001 0.001"/>
    <mesh name="H2017_4_0" file="h2017/assets/H2017_4_0.stl" scale="0.001 0.001 0.001"/>
    <mesh name="H2017_4_1" file="h2017/assets/H2017_4_1.stl" scale="0.001 0.001 0.001"/>
    <mesh name="H2017_5_0" file="h2017/assets/H2017_5_0.stl" scale="0.001 0.001 0.001"/>
    <mesh name="H2017_6_0" file="h2017/assets/H2017_6_0.stl" scale="0.001 0.001 0.001"/>

    <material name="blue" rgba="0.227 0.251 0.31 1"/>
    <material name="metal" rgba="0.65 0.65 0.65 1"/>
  </asset>

  <worldbody>
    <geom type="mesh" group="1" density="0" mesh="H2017_0_0" material="metal"/>
    <body name="link_1" pos="0 0 0.3443">
      <inertial pos="-5e-05 0.11854 -0.059979" quat="0.433782 0.901018 -0.000262548 4.57795e-05" mass="20.253" diaginertia="0.5323 0.467441 0.161829"/>
      <joint name="joint_1" pos="0 0 0" axis="0 0 1" range="-6.2832 6.2832" actuatorfrcrange="-372 372" damping="2000" frictionloss="1"/>
      <!-- <geom size="0.1 0.1" type="cylinder"/> -->
      <geom type="mesh" group="1" density="0" mesh="H2017_1_0" material="blue"/>
      <body name="link_2" pos="0 0.0099 0" quat="0.499898 -0.500102 -0.5 -0.5">
        <inertial pos="0.38055 -1.7e-05 0.22527" quat="0.489962 0.509768 0.51069 0.489152" mass="28.536" diaginertia="3.0424 3.00638 0.148998"/>
        <joint name="joint_2" pos="0 0 0" axis="0 0 1" range="-2.1817 2.1817" actuatorfrcrange="-372 372" damping="2000" frictionloss="1"/>
        <!-- <geom size="0.08 0.375" pos="0.3 0 0.1525" quat="0.707035 0 -0.707179 0" type="cylinder"/> -->
        <geom type="mesh" group="1" density="0" mesh="H2017_2_0" material="blue"/>
        <geom type="mesh" group="1" density="0" mesh="H2017_2_1"  material="metal"/>
        <geom type="mesh" group="1" density="0" mesh="H2017_2_2"  material="blue"/>
        <body name="link_3" pos="0.845 0 0" quat="0.707035 0 0 0.707179">
          <inertial pos="-5.9e-05 -0.008325 0.049527" quat="0.993348 -0.115019 0.000748887 0.00545903" mass="6.421" diaginertia="0.0446304 0.0417332 0.0282805"/>
          <joint name="joint_3" pos="0 0 0" axis="0 0 1" range="-2.7925 2.7925" actuatorfrcrange="-372 372" damping="2000" frictionloss="1"/>
          <geom type="mesh" group="1" density="0" mesh="H2017_3_0" material="blue"/>
          <body name="link_4" pos="0 -0.734 0" quat="0.707035 0.707179 0 0">
            <inertial pos="7.7e-05 0.12896 -0.22056" quat="0.989015 -0.14779 -0.000253538 -0.00257207" mass="7.59" diaginertia="0.60329 0.598264 0.0295216"/>
            <joint name="joint_4" pos="0 0 0" axis="0 0 1" range="-6.2832 6.2832" actuatorfrcrange="-163 163" damping="1600" frictionloss="1"/>
            <!-- <geom size="0.07 0.2" pos="0 0.07 -0.3" quat="0.962425 -0.271547 0 0" type="cylinder"/> -->
            <geom type="mesh" group="1" density="0" mesh="H2017_4_0" material="blue"/>
            <geom type="mesh" group="1" density="0" mesh="H2017_4_1"  material="blue"/>
            <body name="link_5" quat="0.707035 -0.707179 0 0">
              <inertial pos="-6.1e-05 -0.000589 0.048812" quat="0.710562 0.0025434 -0.00204616 0.703627" mass="4.099" diaginertia="0.0238946 0.0213028 0.0145866"/>
              <joint name="joint_5" pos="0 0 0" axis="0 0 1" range="-6.2832 6.2832" actuatorfrcrange="-96 96" damping="1200" frictionloss="1"/>
              <!-- <geom size="0.08 0.075" quat="0.707035 0.707179 0 0" type="cylinder"/> -->
              <geom type="mesh" group="1" density="0" mesh="H2017_5_0" material="blue"/>
              <body name="link_6" pos="0 -0.121 0" quat="0.707035 0.707179 0 0">
                <inertial pos="-3.3e-05 3.6e-05 -0.049443" quat="0.708678 0.705526 0.000127291 0.00288031" mass="0.897" diaginertia="0.00865824 0.00807292 0.00681834"/>
                <joint name="joint_6" pos="0 0 0" axis="0 0 1" range="-6.2832 6.2832" actuatorfrcrange="-50 50" damping="500" frictionloss="1"/>
                <geom type="mesh" group="1" density="0" mesh="H2017_6_0" material="metal"/>
              </body>
            </body>
          </body>
        </body>
      </body>
    </body>
  </worldbody>

	<actuator>
		<position joint="joint_1" kp="2" kv="0.002" ctrlrange="-6.2832 6.2832"/>
		<position joint="joint_2" kp="2" kv="0.002" ctrlrange="-2.1817 2.1817"/>
		<position joint="joint_3" kp="2" kv="0.002" ctrlrange="-2.7925 2.7925"/>
		<position joint="joint_4" kp="2" kv="0.002" ctrlrange="-6.2832 6.2832"/>
		<position joint="joint_5" kp="2" kv="0.002" ctrlrange="-6.2832 6.2832"/>
		<position joint="joint_6" kp="2" kv="0.002" ctrlrange="-6.2832 6.2832"/>
	</actuator>
</mujoco>
