<mujoco model="m0609">

  <asset>
    <mesh name="MF0609_0_0" file="m0609/assets/MF0609_0_0.stl" scale="0.001 0.001 0.001"/>
    <mesh name="MF0609_1_0" file="m0609/assets/MF0609_1_0.stl" scale="0.001 0.001 0.001"/>
    <mesh name="MF0609_2_0" file="m0609/assets/MF0609_2_0.stl" scale="0.001 0.001 0.001"/>
    <mesh name="MF0609_2_1" file="m0609/assets/MF0609_2_1.stl" scale="0.001 0.001 0.001"/>
    <mesh name="MF0609_2_2" file="m0609/assets/MF0609_2_2.stl" scale="0.001 0.001 0.001"/>
    <mesh name="MF0609_3_0" file="m0609/assets/MF0609_3_0.stl" scale="0.001 0.001 0.001"/>
    <mesh name="MF0609_4_0" file="m0609/assets/MF0609_4_0.stl" scale="0.001 0.001 0.001"/>
    <mesh name="MF0609_4_1" file="m0609/assets/MF0609_4_1.stl" scale="0.001 0.001 0.001"/>
    <mesh name="MF0609_5_0" file="m0609/assets/MF0609_5_0.stl" scale="0.001 0.001 0.001"/>
    <mesh name="MF0609_6_0" file="m0609/assets/MF0609_6_0.stl" scale="0.001 0.001 0.001"/>

    <material name="white" rgba="0.9 0.9 0.9 1"/>
    <material name="metal" rgba="0.65 0.65 0.65 1"/>
  </asset>


  <worldbody>
    <geom type="mesh" contype="0" conaffinity="0" group="1" density="0" mesh="MF0609_0_0" material="metal"/>
    <body name="link_1" pos="0 0 0.1345">
      <inertial pos="7.2e-05 0.036227 -0.003417" quat="0.664592 0.747202 0.00267558 -0.000797025" mass="5.02" diaginertia="0.0261951 0.0230285 0.0168144"/>
      <joint name="joint_1" pos="0 0 0" axis="0 0 1" range="-6.2832 6.2832" actuatorfrcrange="-400 400" damping="400" frictionloss="1"/>
      <geom type="mesh" contype="0" conaffinity="0" group="1" density="0" mesh="MF0609_1_0" material="white"/>
      <body name="link_2" pos="0 0.0062 0" quat="0.499898 -0.500102 -0.5 -0.5">
        <inertial pos="0.20447 2.6e-05 0.16005" quat="0.501219 0.498426 0.500493 0.499858" mass="8.04" diaginertia="0.30084 0.298981 0.0267416"/>
        <joint name="joint_2" pos="0 0 0" axis="0 0 1" range="-6.2832 6.2832" actuatorfrcrange="-300 300" damping="400" frictionloss="1"/>
        <geom type="mesh" mesh="MF0609_2_0"/>
        <geom type="mesh" contype="0" conaffinity="0" group="1" density="0" mesh="MF0609_2_0" material="white"/>
        <geom type="mesh" mesh="MF0609_2_1"/>
        <geom type="mesh" contype="0" conaffinity="0" group="1" density="0" mesh="MF0609_2_1" material="metal"/>
        <geom type="mesh" mesh="MF0609_2_2"/>
        <geom type="mesh" contype="0" conaffinity="0" group="1" density="0" mesh="MF0609_2_2" material="white"/>
        <body name="link_3" pos="0.411 0 0" quat="0.707035 0 0 0.707179">
          <inertial pos="-2.2e-05 -0.006867 0.043445" quat="0.749263 -0.0711267 0.0625163 0.655468" mass="3.6" diaginertia="0.0184311 0.0183404 0.0130695"/>
          <joint name="joint_3" pos="0 0 0" axis="0 0 1" range="-2.618 2.618" actuatorfrcrange="-300 300" damping="400" frictionloss="1"/>
          <geom type="mesh" mesh="MF0609_3_0"/>
          <geom type="mesh" contype="0" conaffinity="0" group="1" density="0" mesh="MF0609_3_0" material="white"/>
          <body name="link_4" pos="0 -0.368 0" quat="0.707035 0.707179 0 0">
            <inertial pos="4e-05 0.097079 -0.10981" quat="0.684585 -0.176984 0.177087 0.684587" mass="3.57" diaginertia="0.0820767 0.08035 0.0136913"/>
            <joint name="joint_4" pos="0 0 0" axis="0 0 1" range="-6.2832 6.2832" actuatorfrcrange="-200 200" damping="400" frictionloss="1"/>
            <geom type="mesh" mesh="MF0609_4_0"/>
            <geom type="mesh" contype="0" conaffinity="0" group="1" density="0" mesh="MF0609_4_0" material="white"/>
            <geom type="mesh" mesh="MF0609_4_1"/>
            <geom type="mesh" contype="0" conaffinity="0" group="1" density="0" mesh="MF0609_4_1" material="white"/>
            <body name="link_5" quat="0.707035 -0.707179 0 0">
              <inertial pos="-6.8e-05 0.003827 0.031969" quat="0.998469 0.0548961 -0.000443461 0.00670252" mass="2.83" diaginertia="0.0142753 0.0126184 0.00848208"/>
              <joint name="joint_5" pos="0 0 0" axis="0 0 1" range="-6.2832 6.2832" actuatorfrcrange="-220 220" damping="300" frictionloss="1"/>
              <geom type="mesh" mesh="MF0609_5_0"/>
              <geom type="mesh" contype="0" conaffinity="0" group="1" density="0" mesh="MF0609_5_0" material="white"/>
              <body name="link_6" pos="0 -0.121 0" quat="0.707035 0.707179 0 0">
                <inertial pos="-3e-05 -4.5e-05 -0.0539" quat="0.963897 0.266271 -0.00109467 0.000577053" mass="1.16" diaginertia="0.00802262 0.00540366 0.00538672"/>
                <joint name="joint_6" pos="0 0 0" axis="0 0 1" range="-6.2832 6.2832" actuatorfrcrange="-50 50" damping="200" frictionloss="1"/>
                <geom type="mesh" mesh="MF0609_6_0"/>
                <geom type="mesh" contype="0" conaffinity="0" group="1" density="0" mesh="MF0609_6_0" material="metal"/>
              </body>
            </body>
          </body>
        </body>
      </body>
    </body>
  </worldbody>

    <actuator>
    <position joint="joint_1" kp="10" kv="1" ctrlrange="-6.2832 6.2832"/>
    <position joint="joint_2" kp="10" kv="1" ctrlrange="-6.2832 6.2832"/>
    <position joint="joint_3" kp="10" kv="1" ctrlrange="-2.618 2.618"/>
    <position joint="joint_4" kp="10" kv="1" ctrlrange="-6.2832 6.2832"/>
    <position joint="joint_5" kp="10" kv="1" ctrlrange="-6.2832 6.2832"/>
    <position joint="joint_6" kp="10" kv="1" ctrlrange="-6.2832 6.2832"/>
  </actuator>
</mujoco>
