<mujoco model="e0509">

  <asset>
    <mesh name="E0509_0_0" file="e0509/assets/E0509_0_0.stl" scale="0.001 0.001 0.001"/>
    <mesh name="E0509_1_1" file="e0509/assets/E0509_1_1.stl" scale="0.001 0.001 0.001"/>
    <mesh name="E0509_1_2" file="e0509/assets/E0509_1_2.stl" scale="0.001 0.001 0.001"/>
    <mesh name="E0509_1_3" file="e0509/assets/E0509_1_3.stl" scale="0.001 0.001 0.001"/>
    <mesh name="E0509_1_4" file="e0509/assets/E0509_1_4.stl" scale="0.001 0.001 0.001"/>
    <mesh name="E0509_2_1" file="e0509/assets/E0509_2_1.stl" scale="0.001 0.001 0.001"/>
    <mesh name="E0509_2_2" file="e0509/assets/E0509_2_2.stl" scale="0.001 0.001 0.001"/>
    <mesh name="E0509_3_1" file="e0509/assets/E0509_3_1.stl" scale="0.001 0.001 0.001"/>
    <mesh name="E0509_3_2" file="e0509/assets/E0509_3_2.stl" scale="0.001 0.001 0.001"/>
    <mesh name="E0509_4_1" file="e0509/assets/E0509_4_1.stl" scale="0.001 0.001 0.001"/>
    <mesh name="E0509_4_2" file="e0509/assets/E0509_4_2.stl" scale="0.001 0.001 0.001"/>
    <mesh name="E0509_5_1" file="e0509/assets/E0509_5_1.stl" scale="0.001 0.001 0.001"/>
    <mesh name="E0509_5_2" file="e0509/assets/E0509_5_2.stl" scale="0.001 0.001 0.001"/>
    <mesh name="E0509_6_1" file="e0509/assets/E0509_6_1.stl" scale="0.001 0.001 0.001"/>

    <material name="white" rgba="0.941 0.941 0.941 1"/>
  </asset>

  <worldbody>
    <geom type="mesh" contype="1" conaffinity="1" group="1" density="0" mesh="E0509_0_0" material="white"/>
    <body name="link_1" pos="0 0 0.2045">
      <inertial pos="1e-06 0.049633 -0.049635" quat="0.929158 -0.369673 0.00062326 0.00249849" mass="5.75" diaginertia="0.046214 0.0458051 0.0177669"/>
      <joint name="joint_1" pos="0 0 0" axis="0 0 1" range="-6.2832 6.2832" actuatorfrcrange="-194 194" damping="700"/>
      <geom type="mesh" contype="1" conaffinity="1" group="1" density="0" mesh="E0509_1_1" material="white"/>
      <geom type="mesh" contype="1" conaffinity="1" group="1" density="0" mesh="E0509_1_2" material="white"/>
      <geom type="mesh" contype="1" conaffinity="1" group="1" density="0" mesh="E0509_1_3" material="white"/>
      <geom type="mesh" contype="1" conaffinity="1" group="1" density="0" mesh="E0509_1_4" material="white"/>
      <body name="link_2" quat="0.499998 -0.500002 -0.5 -0.5">
        <inertial pos="0.18647 0 0.17311" quat="0.000354598 0.707123 0.000285146 0.707091" mass="3.461" diaginertia="0.094721 0.091203 0.012039"/>
        <joint name="joint_2" pos="0 0 0" axis="0 0 1" range="-6.2832 6.2832" actuatorfrcrange="-194 194" damping="700"/>
        <geom type="mesh" contype="1" conaffinity="1" group="1" density="0" mesh="E0509_2_1" material="white"/>
        <geom type="mesh" contype="1" conaffinity="1" group="1" density="0" mesh="E0509_2_2" material="white"/>
        <body name="link_3" pos="0.373 0 0" quat="0.707105 0 0 0.707108">
          <inertial pos="1.2e-05 -0.02919 0.062355" quat="0.949876 -0.312625 0.000273945 0.0011091" mass="4.582" diaginertia="0.032606 0.0301114 0.0133836"/>
          <joint name="joint_3" pos="0 0 0" axis="0 0 1" range="-2.7053 2.7053" actuatorfrcrange="-194 194" damping="700"/>
          <geom type="mesh" contype="1" conaffinity="1" group="1" density="0" mesh="E0509_3_1" material="white"/>
          <geom type="mesh" contype="1" conaffinity="1" group="1" density="0" mesh="E0509_3_2" material="white"/>
          <body name="link_4" pos="0 -0.373 0" quat="0.707105 0.707108 0 0">
            <inertial pos="4e-06 0.095573 -0.12813" quat="0.679162 -0.19789 0.197403 0.678683" mass="2.207" diaginertia="0.0384722 0.03547 0.0119838"/>
            <joint name="joint_4" pos="0 0 0" axis="0 0 1" range="-6.2832 6.2832" actuatorfrcrange="-66 66" damping="600"/>
            <geom type="mesh" contype="1" conaffinity="1" group="1" density="0" mesh="E0509_4_1" material="white"/>
            <geom type="mesh" contype="1" conaffinity="1" group="1" density="0" mesh="E0509_4_2" material="white"/>
            <body name="link_5" quat="0.707105 -0.707108 0 0">
              <inertial pos="-3e-06 -0.038009 0.043841" quat="0.95261 -0.304186 0.000232644 0.00218627" mass="3.545" diaginertia="0.023526 0.0226775 0.00998646"/>
              <joint name="joint_5" pos="0 0 0" axis="0 0 1" range="-6.2832 6.2832" actuatorfrcrange="-66 66" damping="600"/>
              <geom type="mesh" contype="1" conaffinity="1" group="1" density="0" mesh="E0509_5_1" material="white"/>
              <geom type="mesh" contype="1" conaffinity="1" group="1" density="0" mesh="E0509_5_2" material="white"/>
              <body name="link_6" pos="0 -0.1725 0" quat="0.707105 0.707108 0 0">
                <inertial pos="5.4e-05 -0.000114 -0.032091" quat="0.491303 0.509421 -0.489812 0.509113" mass="0.721" diaginertia="0.00794241 0.0048274 0.00467698"/>
                <joint name="joint_6" pos="0 0 0" axis="0 0 1" range="-6.2832 6.2832" actuatorfrcrange="-66 66" damping="600"/>
                <geom type="mesh" contype="1" conaffinity="1" group="1" density="0" mesh="E0509_6_1" material="white"/>
              </body>
            </body>
          </body>
        </body>
      </body>
    </body>
  </worldbody>

	<actuator>
		<position joint="joint_1" kp="10" kv="1" ctrlrange="-6.2832 6.2832"/>
		<position joint="joint_2" kp="10" kv="1" ctrlrange="-6.2832 6.2832"/>
		<position joint="joint_3" kp="10" kv="1" ctrlrange="-2.7053 2.7053"/>
		<position joint="joint_4" kp="10" kv="1" ctrlrange="-6.2832 6.2832"/>
		<position joint="joint_5" kp="10" kv="1" ctrlrange="-2.7053 2.7053"/>
		<position joint="joint_6" kp="10" kv="1" ctrlrange="-6.2832 6.2832"/>
	</actuator>

  <contact>
    <exclude body1="link_4" body2="link_6"/>
  </contact>
</mujoco>
