<mujoco model="a0912">

  <asset>
    <mesh name="A0912_0_0" file="a0912/assets/A0912_0_0.stl" scale="0.001 0.001 0.001"/>
    <mesh name="A0912_1_0" file="a0912/assets/A0912_1_0.stl" scale="0.001 0.001 0.001"/>
    <mesh name="A0912_1_1" file="a0912/assets/A0912_1_1.stl" scale="0.001 0.001 0.001"/>
    <mesh name="A0912_1_2" file="a0912/assets/A0912_1_2.stl" scale="0.001 0.001 0.001"/>
    <mesh name="A0912_2_0" file="a0912/assets/A0912_2_0.stl" scale="0.001 0.001 0.001"/>
    <mesh name="A0912_2_1" file="a0912/assets/A0912_2_1.stl" scale="0.001 0.001 0.001"/>
    <mesh name="A0912_2_2" file="a0912/assets/A0912_2_2.stl" scale="0.001 0.001 0.001"/>
    <mesh name="A0912_3_0" file="a0912/assets/A0912_3_0.stl" scale="0.001 0.001 0.001"/>
    <mesh name="A0912_3_1" file="a0912/assets/A0912_3_1.stl" scale="0.001 0.001 0.001"/>
    <mesh name="A0912_4_0" file="a0912/assets/A0912_4_0.stl" scale="0.001 0.001 0.001"/>
    <mesh name="A0912_4_1" file="a0912/assets/A0912_4_1.stl" scale="0.001 0.001 0.001"/>
    <mesh name="A0912_5_0" file="a0912/assets/A0912_5_0.stl" scale="0.001 0.001 0.001"/>
    <mesh name="A0912_5_1" file="a0912/assets/A0912_5_1.stl" scale="0.001 0.001 0.001"/>
    <mesh name="A0912_6_0" file="a0912/assets/A0912_6_0.stl" scale="0.001 0.001 0.001"/>

    <material name="blue" rgba="0.227 0.251 0.31 1"/>
    <material name="metal" rgba="0.65 0.65 0.65 1"/>
    <material name="sky_blue" rgba="0.016 0.933 0.992 1.0"/>
  </asset>

  <worldbody>
    <geom type="mesh" contype="1" conaffinity="1" group="1" density="0" mesh="A0912_0_0" material="metal"/>
    <body name="link_1" pos="0 0 0.195">
      <inertial pos="4.4e-05 0.029982 -0.01112" quat="0.616973 0.786523 0.0212897 -0.0165244" mass="7.863" diaginertia="0.0458411 0.0451317 0.0321783"/>
      <joint name="joint_1" pos="0 0 0" axis="0 0 1" range="-6.2832 6.2832" actuatorfrcrange="-411 411" damping="1200"/>
      <geom type="mesh" contype="1" conaffinity="1" group="1" density="0" mesh="A0912_1_0" material="metal"/>
      <geom type="mesh" contype="1" conaffinity="1" group="1" density="0" mesh="A0912_1_1" material="blue"/>
      <geom type="mesh" contype="1" conaffinity="1" group="1" density="0" mesh="A0912_1_2" material="sky_blue"/>
      <body name="link_2" pos="0 0.039 0" quat="0.499898 -0.500102 -0.5 -0.5">
        <inertial pos="0.19748 0.001426 0.13191" quat="0.494865 0.500903 0.49028 0.513644" mass="10.985" diaginertia="0.676461 0.67447 0.0442288"/>
        <joint name="joint_2" pos="0 0 0" axis="0 0 1" range="-6.2832 6.2832" actuatorfrcrange="-411 411" damping="1200"/>
        <geom type="mesh" contype="1" conaffinity="1" group="1" density="0" mesh="A0912_2_0" material="blue"/>
        <geom type="mesh" contype="1" conaffinity="1" group="1" density="0" mesh="A0912_2_1" material="blue"/>
        <geom type="mesh" contype="1" conaffinity="1" group="1" density="0" mesh="A0912_2_2" material="blue"/>
        <body name="link_3" pos="0.56 0 0" quat="0.707035 0 0 0.707179">
          <inertial pos="8.5e-05 -0.002513 0.032058" quat="0.99956 -0.0295295 -0.00177705 -0.00235181" mass="2.881" diaginertia="0.0127561 0.0114277 0.00805338"/>
          <joint name="joint_3" pos="0 0 0" axis="0 0 1" range="-2.7925 2.7925" actuatorfrcrange="-194 194" damping="900"/>
          <geom type="mesh" contype="1" conaffinity="1" group="1" density="0" mesh="A0912_3_0" material="metal"/>
          <geom type="mesh" contype="1" conaffinity="1" group="1" density="0" mesh="A0912_3_1" material="blue"/>
          <body name="link_4" pos="0 -0.516 0" quat="0.707035 0.707179 0 0">
            <inertial pos="-9.6e-05 0.085314 -0.13975" quat="0.991273 -0.131746 0.000466759 0.00453423" mass="3.273" diaginertia="0.12246 0.120645 0.00961083"/>
            <joint name="joint_4" pos="0 0 0" axis="0 0 1" range="-6.2832 6.2832" actuatorfrcrange="-50 50" damping="600"/>
            <geom type="mesh" contype="1" conaffinity="1" group="1" density="0" mesh="A0912_4_0" material="blue"/>
            <geom type="mesh" contype="1" conaffinity="1" group="1" density="0" mesh="A0912_4_1" material="blue"/>
            <body name="link_5" quat="0.707035 -0.707179 0 0">
              <inertial pos="0.000109 -0.003286 0.01477" quat="0.694836 0.719167 -0.00102984 0.000469357" mass="2.141" diaginertia="0.013145 0.00904965 0.00730513"/>
              <joint name="joint_5" pos="0 0 0" axis="0 0 1" range="-6.2832 6.2832" actuatorfrcrange="-50 50" damping="600"/>
              <geom type="mesh" contype="1" conaffinity="1" group="1" density="0" mesh="A0912_5_0" material="metal"/>
              <geom type="mesh" contype="1" conaffinity="1" group="1" density="0" mesh="A0912_5_1" material="blue"/>
              <body name="link_6" pos="0 -0.124 0" quat="0.707035 0.707179 0 0">
                <inertial pos="-1.9e-05 -6e-06 -0.05227" quat="0.709629 0.704572 -0.0002028 0.00211458" mass="0.784" diaginertia="0.00674032 0.00596965 0.00480143"/>
                <joint name="joint_6" pos="0 0 0" axis="0 0 1" range="-6.2832 6.2832" actuatorfrcrange="-50 50" damping="600"/>
                <geom type="mesh" contype="1" conaffinity="1" group="1" density="0" mesh="A0912_6_0" material="metal"/>
              </body>
            </body>
          </body>
        </body>
      </body>
    </body>
  </worldbody>
  
	<actuator>
		<position joint="joint_1" kp="10" kv="1" ctrlrange="-6.2832 6.2832"/>
		<position joint="joint_2" kp="10" kv="1" ctrlrange="-6.2832 6.2832"/>
		<position joint="joint_3" kp="10" kv="1" ctrlrange="-2.7925 2.7925"/>
		<position joint="joint_4" kp="10" kv="1" ctrlrange="-6.2832 6.2832"/>
		<position joint="joint_5" kp="10" kv="1" ctrlrange="-6.2832 6.2832"/>
		<position joint="joint_6" kp="10" kv="1" ctrlrange="-6.2832 6.2832"/>
	</actuator>
</mujoco>
